Traceback (most recent call last):
  File "C:\Python310\lib\site-packages\jupyter_cache\executors\utils.py", line 51, in single_nb_execution
    executenb(
  File "C:\Python310\lib\site-packages\nbclient\client.py", line 1204, in execute
    return NotebookClient(nb=nb, resources=resources, km=km, **kwargs).execute()
  File "C:\Python310\lib\site-packages\nbclient\util.py", line 84, in wrapped
    return just_run(coro(*args, **kwargs))
  File "C:\Python310\lib\site-packages\nbclient\util.py", line 62, in just_run
    return loop.run_until_complete(coro)
  File "C:\Python310\lib\asyncio\base_events.py", line 646, in run_until_complete
    return future.result()
  File "C:\Python310\lib\site-packages\nbclient\client.py", line 663, in async_execute
    await self.async_execute_cell(
  File "C:\Python310\lib\site-packages\nbclient\client.py", line 965, in async_execute_cell
    await self._check_raise_for_error(cell, cell_index, exec_reply)
  File "C:\Python310\lib\site-packages\nbclient\client.py", line 862, in _check_raise_for_error
    raise CellExecutionError.from_cell_and_msg(cell, exec_reply_content)
nbclient.exceptions.CellExecutionError: An error occurred while executing the following cell:
------------------
display("The data type of the tweet created_utc at is: " + type(recent_submission.created_utc).__name__)
display("The created_utc at is: " + str(recent_submission.created_utc))

# convert the utc to a different datetime
import datetime
converted_time = datetime.datetime.fromtimestamp(recent_submission.created_utc)
display("The data type of the converted_time at is: " + type(converted_time).__name__)
display("The converted_time at is: " + str(readable_time))
------------------

[1;31m---------------------------------------------------------------------------[0m
[1;31mNameError[0m                                 Traceback (most recent call last)
Input [1;32mIn [10][0m, in [0;36m<cell line: 8>[1;34m()[0m
[0;32m      6[0m converted_time [38;5;241m=[39m datetime[38;5;241m.[39mdatetime[38;5;241m.[39mfromtimestamp(recent_submission[38;5;241m.[39mcreated_utc)
[0;32m      7[0m display([38;5;124m"[39m[38;5;124mThe data type of the converted_time at is: [39m[38;5;124m"[39m [38;5;241m+[39m [38;5;28mtype[39m(converted_time)[38;5;241m.[39m[38;5;18m__name__[39m)
[1;32m----> 8[0m display([38;5;124m"[39m[38;5;124mThe converted_time at is: [39m[38;5;124m"[39m [38;5;241m+[39m [38;5;28mstr[39m([43mreadable_time[49m))

[1;31mNameError[0m: name 'readable_time' is not defined
NameError: name 'readable_time' is not defined

